<?xml version="1.0" ?>
<robot name="URDF">

<material name="silver">
  <color rgba="0.700 0.700 0.700 1.000"/>
</material>

<link name="base_link">
  <inertial>
    <origin rpy="0 0 0" xyz="-0.5 0.25000000000000006 -0.5"/>
    <mass value="530.0"/>
    <inertia ixx="55.208333333333314" ixy="1.4210854715202004e-14" ixz="0.0" iyy="88.33333333333331" iyz="1.4210854715202004e-14" izz="55.208333333333314"/>
  </inertial>
  <visual>
    <origin rpy="0 0 0" xyz="0 0 0"/>
    <geometry>
      <mesh filename="meshes/base_link.stl" scale="0.001 0.001 0.001"/>
    </geometry>
    <material name="silver"/>
    <material/>
  </visual>
  <collision>
    <origin rpy="0 0 0" xyz="0 0 0"/>
    <geometry>
      <mesh filename="meshes/base_link.stl" scale="0.001 0.001 0.001"/>
    </geometry>
  </collision>
</link>

<link name="Wheel_2020_v61">
  <inertial>
    <origin rpy="0 0 0" xyz="-2.5272903137094332e-17 1.2636451568547173e-16 -0.03802583860928843"/>
    <mass value="3.051693360749828"/>
    <inertia ixx="0.01329651401605636" ixy="-2.2683201162306266e-32" ixz="2.932748533628609e-18" iyy="0.013296514016055916" iyz="-2.0833754724970597e-17" izz="0.022874433012492104"/>
  </inertial>
  <visual>
    <origin rpy="0 0 0" xyz="-0.0 -0.0 1.0"/>
    <geometry>
      <mesh filename="meshes/Wheel_2020_v61.stl" scale="0.001 0.001 0.001"/>
    </geometry>
    <material name="silver"/>
    <material/>
  </visual>
  <collision>
    <origin rpy="0 0 0" xyz="-0.0 -0.0 1.0"/>
    <geometry>
      <mesh filename="meshes/Wheel_2020_v61.stl" scale="0.001 0.001 0.001"/>
    </geometry>
  </collision>
</link>

<link name="Wheel_2020_v6_21">
  <inertial>
    <origin rpy="0 0 0" xyz="-2.220446049250313e-16 2.484890483942389e-16 -0.03802583860928843"/>
    <mass value="3.051693360749828"/>
    <inertia ixx="0.01329651401605636" ixy="0.0" ixz="8.881784197001252e-16" iyy="0.013296514016053251" iyz="-2.083375472497045e-17" izz="0.02287443301249059"/>
  </inertial>
  <visual>
    <origin rpy="0 0 0" xyz="1.0 -0.0 1.0"/>
    <geometry>
      <mesh filename="meshes/Wheel_2020_v6_21.stl" scale="0.001 0.001 0.001"/>
    </geometry>
    <material name="silver"/>
    <material/>
  </visual>
  <collision>
    <origin rpy="0 0 0" xyz="1.0 -0.0 1.0"/>
    <geometry>
      <mesh filename="meshes/Wheel_2020_v6_21.stl" scale="0.001 0.001 0.001"/>
    </geometry>
  </collision>
</link>

<link name="Wheel_2020_v6_11">
  <inertial>
    <origin rpy="0 0 0" xyz="2.5272903137094347e-17 1.2636451568547173e-16 0.03802583860928854"/>
    <mass value="3.051693360749828"/>
    <inertia ixx="0.013296514016054925" ixy="9.745882316681677e-33" ixz="2.932748533628609e-18" iyy="0.013296514016054821" iyz="2.0833754724970585e-17" izz="0.022874433012492104"/>
  </inertial>
  <visual>
    <origin rpy="0 0 0" xyz="-0.0 -0.0 -0.0"/>
    <geometry>
      <mesh filename="meshes/Wheel_2020_v6_11.stl" scale="0.001 0.001 0.001"/>
    </geometry>
    <material name="silver"/>
    <material/>
  </visual>
  <collision>
    <origin rpy="0 0 0" xyz="-0.0 -0.0 -0.0"/>
    <geometry>
      <mesh filename="meshes/Wheel_2020_v6_11.stl" scale="0.001 0.001 0.001"/>
    </geometry>
  </collision>
</link>

<link name="Wheel_2020_v6_31">
  <inertial>
    <origin rpy="0 0 0" xyz="-2.220446049250313e-16 2.484890483942389e-16 0.03802583860928857"/>
    <mass value="3.051693360749828"/>
    <inertia ixx="0.01329651401605493" ixy="6.902532920683853e-31" ixz="1.942890293094024e-16" iyy="0.013296514016054584" iyz="2.0833754724970585e-17" izz="0.022874433012491924"/>
  </inertial>
  <visual>
    <origin rpy="0 0 0" xyz="1.0 -0.0 -0.0"/>
    <geometry>
      <mesh filename="meshes/Wheel_2020_v6_31.stl" scale="0.001 0.001 0.001"/>
    </geometry>
    <material name="silver"/>
    <material/>
  </visual>
  <collision>
    <origin rpy="0 0 0" xyz="1.0 -0.0 -0.0"/>
    <geometry>
      <mesh filename="meshes/Wheel_2020_v6_31.stl" scale="0.001 0.001 0.001"/>
    </geometry>
  </collision>
</link>

<joint name="Rev15" type="continuous">
  <origin rpy="0 0 0" xyz="0.0 0.0 -1.0"/>
  <parent link="base_link"/>
  <child link="Wheel_2020_v61"/>
  <axis xyz="0.0 0.0 -1.0"/>
</joint>
<transmission name="Rev15_tran">
  <type>transmission_interface/SimpleTransmission</type>
  <joint name="Rev15">
    <hardwareInterface>PositionJointInterface</hardwareInterface>
  </joint>
  <actuator name="Rev15_actr">
    <hardwareInterface>PositionJointInterface</hardwareInterface>
    <mechanicalReduction>1</mechanicalReduction>
  </actuator>
</transmission>

<joint name="Rev16" type="continuous">
  <origin rpy="0 0 0" xyz="-1.0 0.0 -1.0"/>
  <parent link="base_link"/>
  <child link="Wheel_2020_v6_21"/>
  <axis xyz="0.0 0.0 -1.0"/>
</joint>
<transmission name="Rev16_tran">
  <type>transmission_interface/SimpleTransmission</type>
  <joint name="Rev16">
    <hardwareInterface>PositionJointInterface</hardwareInterface>
  </joint>
  <actuator name="Rev16_actr">
    <hardwareInterface>PositionJointInterface</hardwareInterface>
    <mechanicalReduction>1</mechanicalReduction>
  </actuator>
</transmission>

<joint name="Rev17" type="continuous">
  <origin rpy="0 0 0" xyz="0.0 0.0 0.0"/>
  <parent link="base_link"/>
  <child link="Wheel_2020_v6_11"/>
  <axis xyz="0.0 0.0 -1.0"/>
</joint>
<transmission name="Rev17_tran">
  <type>transmission_interface/SimpleTransmission</type>
  <joint name="Rev17">
    <hardwareInterface>PositionJointInterface</hardwareInterface>
  </joint>
  <actuator name="Rev17_actr">
    <hardwareInterface>PositionJointInterface</hardwareInterface>
    <mechanicalReduction>1</mechanicalReduction>
  </actuator>
</transmission>

<joint name="Rev18" type="continuous">
  <origin rpy="0 0 0" xyz="-1.0 0.0 0.0"/>
  <parent link="base_link"/>
  <child link="Wheel_2020_v6_31"/>
  <axis xyz="0.0 0.0 -1.0"/>
</joint>
<transmission name="Rev18_tran">
  <type>transmission_interface/SimpleTransmission</type>
  <joint name="Rev18">
    <hardwareInterface>PositionJointInterface</hardwareInterface>
  </joint>
  <actuator name="Rev18_actr">
    <hardwareInterface>PositionJointInterface</hardwareInterface>
    <mechanicalReduction>1</mechanicalReduction>
  </actuator>
</transmission>

</robot>
